Traceback (most recent call last):
  File "/Users/rahimrasool/opt/anaconda3/lib/python3.9/site-packages/jupyter_cache/executors/utils.py", line 51, in single_nb_execution
    executenb(
  File "/Users/rahimrasool/opt/anaconda3/lib/python3.9/site-packages/nbclient/client.py", line 1204, in execute
    return NotebookClient(nb=nb, resources=resources, km=km, **kwargs).execute()
  File "/Users/rahimrasool/opt/anaconda3/lib/python3.9/site-packages/nbclient/util.py", line 84, in wrapped
    return just_run(coro(*args, **kwargs))
  File "/Users/rahimrasool/opt/anaconda3/lib/python3.9/site-packages/nbclient/util.py", line 62, in just_run
    return loop.run_until_complete(coro)
  File "/Users/rahimrasool/opt/anaconda3/lib/python3.9/asyncio/base_events.py", line 647, in run_until_complete
    return future.result()
  File "/Users/rahimrasool/opt/anaconda3/lib/python3.9/site-packages/nbclient/client.py", line 663, in async_execute
    await self.async_execute_cell(
  File "/Users/rahimrasool/opt/anaconda3/lib/python3.9/site-packages/nbclient/client.py", line 965, in async_execute_cell
    await self._check_raise_for_error(cell, cell_index, exec_reply)
  File "/Users/rahimrasool/opt/anaconda3/lib/python3.9/site-packages/nbclient/client.py", line 862, in _check_raise_for_error
    raise CellExecutionError.from_cell_and_msg(cell, exec_reply_content)
nbclient.exceptions.CellExecutionError: An error occurred while executing the following cell:
------------------
stops_race_dummies = pd.get_dummies(stops_df, columns = ['DriverRace'])
stops_race_dummies['BeatCode'] = stops_race_dummies['BeatCode'].astype('str').str.zfill(4)
Beat_Race_group = stops_race_dummies.groupby('BeatCode').sum()[stops_race_dummies.columns[11:]]
Beat_Race_group.reset_index(inplace=True)
------------------

[0;31m---------------------------------------------------------------------------[0m
[0;31mKeyError[0m                                  Traceback (most recent call last)
Input [0;32mIn [88][0m, in [0;36m<cell line: 3>[0;34m()[0m
[1;32m      1[0m stops_race_dummies [38;5;241m=[39m pd[38;5;241m.[39mget_dummies(stops_df, columns [38;5;241m=[39m [[38;5;124m'[39m[38;5;124mDriverRace[39m[38;5;124m'[39m])
[1;32m      2[0m stops_race_dummies[[38;5;124m'[39m[38;5;124mBeatCode[39m[38;5;124m'[39m] [38;5;241m=[39m stops_race_dummies[[38;5;124m'[39m[38;5;124mBeatCode[39m[38;5;124m'[39m][38;5;241m.[39mastype([38;5;124m'[39m[38;5;124mstr[39m[38;5;124m'[39m)[38;5;241m.[39mstr[38;5;241m.[39mzfill([38;5;241m4[39m)
[0;32m----> 3[0m Beat_Race_group [38;5;241m=[39m [43mstops_race_dummies[49m[38;5;241;43m.[39;49m[43mgroupby[49m[43m([49m[38;5;124;43m'[39;49m[38;5;124;43mBeatCode[39;49m[38;5;124;43m'[39;49m[43m)[49m[38;5;241;43m.[39;49m[43msum[49m[43m([49m[43m)[49m[43m[[49m[43mstops_race_dummies[49m[38;5;241;43m.[39;49m[43mcolumns[49m[43m[[49m[38;5;241;43m11[39;49m[43m:[49m[43m][49m[43m][49m
[1;32m      4[0m Beat_Race_group[38;5;241m.[39mreset_index(inplace[38;5;241m=[39m[38;5;28;01mTrue[39;00m)

File [0;32m~/opt/anaconda3/lib/python3.9/site-packages/pandas/core/frame.py:3511[0m, in [0;36mDataFrame.__getitem__[0;34m(self, key)[0m
[1;32m   3509[0m     [38;5;28;01mif[39;00m is_iterator(key):
[1;32m   3510[0m         key [38;5;241m=[39m [38;5;28mlist[39m(key)
[0;32m-> 3511[0m     indexer [38;5;241m=[39m [38;5;28;43mself[39;49m[38;5;241;43m.[39;49m[43mcolumns[49m[38;5;241;43m.[39;49m[43m_get_indexer_strict[49m[43m([49m[43mkey[49m[43m,[49m[43m [49m[38;5;124;43m"[39;49m[38;5;124;43mcolumns[39;49m[38;5;124;43m"[39;49m[43m)[49m[[38;5;241m1[39m]
[1;32m   3513[0m [38;5;66;03m# take() does not accept boolean indexers[39;00m
[1;32m   3514[0m [38;5;28;01mif[39;00m [38;5;28mgetattr[39m(indexer, [38;5;124m"[39m[38;5;124mdtype[39m[38;5;124m"[39m, [38;5;28;01mNone[39;00m) [38;5;241m==[39m [38;5;28mbool[39m:

File [0;32m~/opt/anaconda3/lib/python3.9/site-packages/pandas/core/indexes/base.py:5782[0m, in [0;36mIndex._get_indexer_strict[0;34m(self, key, axis_name)[0m
[1;32m   5779[0m [38;5;28;01melse[39;00m:
[1;32m   5780[0m     keyarr, indexer, new_indexer [38;5;241m=[39m [38;5;28mself[39m[38;5;241m.[39m_reindex_non_unique(keyarr)
[0;32m-> 5782[0m [38;5;28;43mself[39;49m[38;5;241;43m.[39;49m[43m_raise_if_missing[49m[43m([49m[43mkeyarr[49m[43m,[49m[43m [49m[43mindexer[49m[43m,[49m[43m [49m[43maxis_name[49m[43m)[49m
[1;32m   5784[0m keyarr [38;5;241m=[39m [38;5;28mself[39m[38;5;241m.[39mtake(indexer)
[1;32m   5785[0m [38;5;28;01mif[39;00m [38;5;28misinstance[39m(key, Index):
[1;32m   5786[0m     [38;5;66;03m# GH 42790 - Preserve name from an Index[39;00m

File [0;32m~/opt/anaconda3/lib/python3.9/site-packages/pandas/core/indexes/base.py:5845[0m, in [0;36mIndex._raise_if_missing[0;34m(self, key, indexer, axis_name)[0m
[1;32m   5842[0m     [38;5;28;01mraise[39;00m [38;5;167;01mKeyError[39;00m([38;5;124mf[39m[38;5;124m"[39m[38;5;124mNone of [[39m[38;5;132;01m{[39;00mkey[38;5;132;01m}[39;00m[38;5;124m] are in the [[39m[38;5;132;01m{[39;00maxis_name[38;5;132;01m}[39;00m[38;5;124m][39m[38;5;124m"[39m)
[1;32m   5844[0m not_found [38;5;241m=[39m [38;5;28mlist[39m(ensure_index(key)[missing_mask[38;5;241m.[39mnonzero()[[38;5;241m0[39m]][38;5;241m.[39munique())
[0;32m-> 5845[0m [38;5;28;01mraise[39;00m [38;5;167;01mKeyError[39;00m([38;5;124mf[39m[38;5;124m"[39m[38;5;132;01m{[39;00mnot_found[38;5;132;01m}[39;00m[38;5;124m not in index[39m[38;5;124m"[39m)

[0;31mKeyError[0m: "['Time', 'Hour'] not in index"
KeyError: "['Time', 'Hour'] not in index"

